 * Serving Flask app 'app'
 * Debug mode: off
[31m[1mWARNING: This is a development server. Do not use it in a production deployment. Use a production WSGI server instead.[0m
 * Running on http://127.0.0.1:5000
[33mPress CTRL+C to quit[0m
[2025-07-18 01:02:15,561] ERROR in app: Exception on / [GET]
Traceback (most recent call last):
  File "/usr/local/lib64/python3.9/site-packages/mysql/connector/connection_cext.py", line 354, in _open_connection
    self._cmysql.connect(**cnx_kwargs)
_mysql_connector.MySQLInterfaceError: Access denied for user 'root'@'localhost'

The above exception was the direct cause of the following exception:

Traceback (most recent call last):
  File "/usr/local/lib/python3.9/site-packages/flask/app.py", line 1511, in wsgi_app
    response = self.full_dispatch_request()
  File "/usr/local/lib/python3.9/site-packages/flask/app.py", line 919, in full_dispatch_request
    rv = self.handle_user_exception(e)
  File "/usr/local/lib/python3.9/site-packages/flask/app.py", line 917, in full_dispatch_request
    rv = self.dispatch_request()
  File "/usr/local/lib/python3.9/site-packages/flask/app.py", line 902, in dispatch_request
    return self.ensure_sync(self.view_functions[rule.endpoint])(**view_args)  # type: ignore[no-any-return]
  File "/home/ec2-user/flask-app/app.py", line 38, in index
    conn = mysql.connector.connect(**db_config)
  File "/usr/local/lib64/python3.9/site-packages/mysql/connector/pooling.py", line 322, in connect
    return CMySQLConnection(*args, **kwargs)
  File "/usr/local/lib64/python3.9/site-packages/mysql/connector/connection_cext.py", line 142, in __init__
    self.connect(**kwargs)
  File "/usr/local/lib64/python3.9/site-packages/mysql/connector/abstracts.py", line 1605, in connect
    self._open_connection()
  File "/usr/local/lib64/python3.9/site-packages/mysql/connector/connection_cext.py", line 360, in _open_connection
    raise get_mysql_exception(
mysql.connector.errors.ProgrammingError: 1698 (28000): Access denied for user 'root'@'localhost'
127.0.0.1 - - [18/Jul/2025 01:02:15] "[35m[1mGET / HTTP/1.1[0m" 500 -
 * Serving Flask app 'app'
 * Debug mode: off
[31m[1mWARNING: This is a development server. Do not use it in a production deployment. Use a production WSGI server instead.[0m
 * Running on http://127.0.0.1:5000
[33mPress CTRL+C to quit[0m
[2025-07-18 01:04:07,008] ERROR in app: Exception on / [GET]
Traceback (most recent call last):
  File "/usr/local/lib64/python3.9/site-packages/mysql/connector/connection_cext.py", line 354, in _open_connection
    self._cmysql.connect(**cnx_kwargs)
_mysql_connector.MySQLInterfaceError: Access denied for user 'root'@'localhost'

The above exception was the direct cause of the following exception:

Traceback (most recent call last):
  File "/usr/local/lib/python3.9/site-packages/flask/app.py", line 1511, in wsgi_app
    response = self.full_dispatch_request()
  File "/usr/local/lib/python3.9/site-packages/flask/app.py", line 919, in full_dispatch_request
    rv = self.handle_user_exception(e)
  File "/usr/local/lib/python3.9/site-packages/flask/app.py", line 917, in full_dispatch_request
    rv = self.dispatch_request()
  File "/usr/local/lib/python3.9/site-packages/flask/app.py", line 902, in dispatch_request
    return self.ensure_sync(self.view_functions[rule.endpoint])(**view_args)  # type: ignore[no-any-return]
  File "/home/ec2-user/flask-app/app.py", line 38, in index
    conn = mysql.connector.connect(**db_config)
  File "/usr/local/lib64/python3.9/site-packages/mysql/connector/pooling.py", line 322, in connect
    return CMySQLConnection(*args, **kwargs)
  File "/usr/local/lib64/python3.9/site-packages/mysql/connector/connection_cext.py", line 142, in __init__
    self.connect(**kwargs)
  File "/usr/local/lib64/python3.9/site-packages/mysql/connector/abstracts.py", line 1605, in connect
    self._open_connection()
  File "/usr/local/lib64/python3.9/site-packages/mysql/connector/connection_cext.py", line 360, in _open_connection
    raise get_mysql_exception(
mysql.connector.errors.ProgrammingError: 1698 (28000): Access denied for user 'root'@'localhost'
127.0.0.1 - - [18/Jul/2025 01:04:07] "[35m[1mGET / HTTP/1.1[0m" 500 -
[2025-07-18 01:05:03,948] ERROR in app: Exception on / [GET]
Traceback (most recent call last):
  File "/usr/local/lib64/python3.9/site-packages/mysql/connector/connection_cext.py", line 354, in _open_connection
    self._cmysql.connect(**cnx_kwargs)
_mysql_connector.MySQLInterfaceError: Access denied for user 'root'@'localhost'

The above exception was the direct cause of the following exception:

Traceback (most recent call last):
  File "/usr/local/lib/python3.9/site-packages/flask/app.py", line 1511, in wsgi_app
    response = self.full_dispatch_request()
  File "/usr/local/lib/python3.9/site-packages/flask/app.py", line 919, in full_dispatch_request
    rv = self.handle_user_exception(e)
  File "/usr/local/lib/python3.9/site-packages/flask/app.py", line 917, in full_dispatch_request
    rv = self.dispatch_request()
  File "/usr/local/lib/python3.9/site-packages/flask/app.py", line 902, in dispatch_request
    return self.ensure_sync(self.view_functions[rule.endpoint])(**view_args)  # type: ignore[no-any-return]
  File "/home/ec2-user/flask-app/app.py", line 38, in index
    conn = mysql.connector.connect(**db_config)
  File "/usr/local/lib64/python3.9/site-packages/mysql/connector/pooling.py", line 322, in connect
    return CMySQLConnection(*args, **kwargs)
  File "/usr/local/lib64/python3.9/site-packages/mysql/connector/connection_cext.py", line 142, in __init__
    self.connect(**kwargs)
  File "/usr/local/lib64/python3.9/site-packages/mysql/connector/abstracts.py", line 1605, in connect
    self._open_connection()
  File "/usr/local/lib64/python3.9/site-packages/mysql/connector/connection_cext.py", line 360, in _open_connection
    raise get_mysql_exception(
mysql.connector.errors.ProgrammingError: 1698 (28000): Access denied for user 'root'@'localhost'
127.0.0.1 - - [18/Jul/2025 01:05:03] "[35m[1mGET / HTTP/1.1[0m" 500 -
127.0.0.1 - - [18/Jul/2025 01:05:04] "[33mGET /favicon.ico HTTP/1.1[0m" 404 -
[2025-07-18 01:05:06,672] ERROR in app: Exception on / [GET]
Traceback (most recent call last):
  File "/usr/local/lib64/python3.9/site-packages/mysql/connector/connection_cext.py", line 354, in _open_connection
    self._cmysql.connect(**cnx_kwargs)
_mysql_connector.MySQLInterfaceError: Access denied for user 'root'@'localhost'

The above exception was the direct cause of the following exception:

Traceback (most recent call last):
  File "/usr/local/lib/python3.9/site-packages/flask/app.py", line 1511, in wsgi_app
    response = self.full_dispatch_request()
  File "/usr/local/lib/python3.9/site-packages/flask/app.py", line 919, in full_dispatch_request
    rv = self.handle_user_exception(e)
  File "/usr/local/lib/python3.9/site-packages/flask/app.py", line 917, in full_dispatch_request
    rv = self.dispatch_request()
  File "/usr/local/lib/python3.9/site-packages/flask/app.py", line 902, in dispatch_request
    return self.ensure_sync(self.view_functions[rule.endpoint])(**view_args)  # type: ignore[no-any-return]
  File "/home/ec2-user/flask-app/app.py", line 38, in index
    conn = mysql.connector.connect(**db_config)
  File "/usr/local/lib64/python3.9/site-packages/mysql/connector/pooling.py", line 322, in connect
    return CMySQLConnection(*args, **kwargs)
  File "/usr/local/lib64/python3.9/site-packages/mysql/connector/connection_cext.py", line 142, in __init__
    self.connect(**kwargs)
  File "/usr/local/lib64/python3.9/site-packages/mysql/connector/abstracts.py", line 1605, in connect
    self._open_connection()
  File "/usr/local/lib64/python3.9/site-packages/mysql/connector/connection_cext.py", line 360, in _open_connection
    raise get_mysql_exception(
mysql.connector.errors.ProgrammingError: 1698 (28000): Access denied for user 'root'@'localhost'
127.0.0.1 - - [18/Jul/2025 01:05:06] "[35m[1mGET / HTTP/1.1[0m" 500 -
[2025-07-18 01:05:07,210] ERROR in app: Exception on / [GET]
Traceback (most recent call last):
  File "/usr/local/lib64/python3.9/site-packages/mysql/connector/connection_cext.py", line 354, in _open_connection
    self._cmysql.connect(**cnx_kwargs)
_mysql_connector.MySQLInterfaceError: Access denied for user 'root'@'localhost'

The above exception was the direct cause of the following exception:

Traceback (most recent call last):
  File "/usr/local/lib/python3.9/site-packages/flask/app.py", line 1511, in wsgi_app
    response = self.full_dispatch_request()
  File "/usr/local/lib/python3.9/site-packages/flask/app.py", line 919, in full_dispatch_request
    rv = self.handle_user_exception(e)
  File "/usr/local/lib/python3.9/site-packages/flask/app.py", line 917, in full_dispatch_request
    rv = self.dispatch_request()
  File "/usr/local/lib/python3.9/site-packages/flask/app.py", line 902, in dispatch_request
    return self.ensure_sync(self.view_functions[rule.endpoint])(**view_args)  # type: ignore[no-any-return]
  File "/home/ec2-user/flask-app/app.py", line 38, in index
    conn = mysql.connector.connect(**db_config)
  File "/usr/local/lib64/python3.9/site-packages/mysql/connector/pooling.py", line 322, in connect
    return CMySQLConnection(*args, **kwargs)
  File "/usr/local/lib64/python3.9/site-packages/mysql/connector/connection_cext.py", line 142, in __init__
    self.connect(**kwargs)
  File "/usr/local/lib64/python3.9/site-packages/mysql/connector/abstracts.py", line 1605, in connect
    self._open_connection()
  File "/usr/local/lib64/python3.9/site-packages/mysql/connector/connection_cext.py", line 360, in _open_connection
    raise get_mysql_exception(
mysql.connector.errors.ProgrammingError: 1698 (28000): Access denied for user 'root'@'localhost'
127.0.0.1 - - [18/Jul/2025 01:05:07] "[35m[1mGET / HTTP/1.1[0m" 500 -
 * Serving Flask app 'app'
 * Debug mode: off
[31m[1mWARNING: This is a development server. Do not use it in a production deployment. Use a production WSGI server instead.[0m
 * Running on http://127.0.0.1:5000
[33mPress CTRL+C to quit[0m
 * Serving Flask app 'app'
 * Debug mode: off
[31m[1mWARNING: This is a development server. Do not use it in a production deployment. Use a production WSGI server instead.[0m
 * Running on http://127.0.0.1:5000
[33mPress CTRL+C to quit[0m
 * Serving Flask app 'app'
 * Debug mode: off
[31m[1mWARNING: This is a development server. Do not use it in a production deployment. Use a production WSGI server instead.[0m
 * Running on http://127.0.0.1:5000
[33mPress CTRL+C to quit[0m
